Workbook

Sheet Panduan
A1: Verifikasi Manual Intelligent K-Means — Wisata Jakarta AI
A3: Alur sheet:
A4: 1. Data_Awal — input 7 fitur (sel kuning).
A5: 2. Normalisasi — Z-Score otomatis (RATA.RATA, DEV.STANDAR.P).
A6: 3. Inisialisasi — centroid awal K-Means++ (indeks POI).
A7: 4. Konvergensi — iterasi lengkap: jarak, assignment, centroid baru, WCSS.
A8: 5. Hasil_Cluster — ringkasan centroid final & label POI.
A9: 6. Evaluasi_K — WCSS & Silhouette untuk K=2..max (Python ref).
A10: 7. Verifikasi — bandingkan selisih Excel vs program.
A12: Parameter: K=3, max_iter=300, tol=0.0001, random_state=42
A13: Backend: backend/services/kmeans_service.py
A14: Locale formula: Indonesia (;). DEV.STANDAR.P = ddof=0 (sama sklearn StandardScaler).

Sheet Data_Awal
A1: POI ID | B1: Nama POI | C1: Latitude | D1: Longitude | E1: Semantic Score | F1: Jarak Hotel (m) | G1: Jarak Halte (m) | H1: Restoran 500m | I1: Minimarket 500m
A2: 1 | B2: POI Sample 01 | C2: -6.1114168 | D2: 106.85216 | E2: 0.93598129 | F2: 1609.0267 | G2: 1383.6684 | H2: 5 | I2: 12
A3: 2 | B3: POI Sample 02 | C3: -6.2716382 | D3: 106.81292 | E3: 0.39382072 | F3: 10755.914 | G3: 1798.8341 | H3: 15 | I3: 4
A4: 3 | B4: POI Sample 03 | C4: -6.2012027 | D4: 106.99788 | E4: 0.84937143 | F4: 11525.4 | G4: 585.45922 | H4: 9 | I4: 4
A5: 4 | B5: POI Sample 04 | C5: -6.1347044 | D5: 106.74548 | E5: 0.36084018 | F5: 2227.7281 | G5: 283.52214 | H5: 8 | I5: 5
A6: 5 | B6: POI Sample 05 | C6: -6.2892879 | D6: 106.99717 | E6: 0.76602742 | F6: 8024.7463 | G6: 170.77232 | H6: 2 | I6: 3
A7: 6 | B7: POI Sample 06 | C7: -6.2369791 | D7: 106.96297 | E7: 0.65362207 | F7: 774.91415 | G7: 2072.5031 | H7: 15 | I7: 11
A8: 7 | B8: POI Sample 07 | C8: -6.1322636 | D8: 107.01308 | E8: 0.39763396 | F8: 2657.3838 | G8: 1685.3787 | H8: 4 | I8: 0
A9: 8 | B9: POI Sample 08 | C9: -6.1090754 | D9: 106.78484 | E9: 0.7525984 | F9: 10494.538 | G9: 2404.3824 | H9: 0 | I9: 3
A10: 9 | B10: POI Sample 09 | C10: -6.1553121 | D10: 107.02583 | E10: 0.4051031 | F10: 5833.2585 | G10: 770.48692 | H10: 5 | I10: 7
A11: 10 | B11: POI Sample 10 | C11: -6.1796911 | D11: 106.83908 | E11: 0.74712353 | F11: 9561.3357 | G11: 1705.3935 | H11: 17 | I11: 2
A12: 11 | B12: POI Sample 11 | C12: -6.0771105 | D12: 107.03917 | E12: 0.73233858 | F12: 3599.2549 | G12: 2557.9663 | H12: 4 | I12: 6
A13: 12 | B13: POI Sample 12 | C13: -6.2629259 | D13: 106.86016 | E13: 0.3768468 | F13: 4301.5017 | G13: 2558.6749 | H13: 8 | I13: 0
... A51: 50 | B51: POI Sample 50 | C51: -6.0869217 | D51: 106.8181 | E51: 0.74725613 | F51: 4105.2457 | G51: 1518.0252 | H51: 16 | I51: 6
A53: K (target) | B53: 3
A54: random_state | B54: 42
A55: tolerance | B55: 0.0001

Sheet Normalisasi
A1: POI ID | B1: Nama POI | C1: Latitude | D1: Longitude | E1: Semantic Score | F1: Jarak Hotel (m) | G1: Jarak Halte (m) | H1: Restoran 500m | I1: Minimarket 500m | J1: Z Latitude | K1: Z Longitude | L1: Z Semantic Score | M1: Z Jarak Hotel (m) | N1: Z Jarak Halte (m) | O1: Z Restoran 500m | P1: Z Minimarket 500m | Q1: Max |Selisih| | R1: Py Z Latitude | S1: Py Z Longitude | T1: Py Z Semantic Score | U1: Py Z Jarak Hotel (m) | V1: Py Z Jarak Halte (m) | W1: Py Z Restoran 500m | X1: Py Z Minimarket 500m
A2: =Data_Awal!A2 | B2: =Data_Awal!B2 | C2: =Data_Awal!C2 | D2: =Data_Awal!D2 | E2: =Data_Awal!E2 | F2: =Data_Awal!F2 | G2: =Data_Awal!G2 | H2: =Data_Awal!H2 | I2: =Data_Awal!I2 | J2: =JIKA(Normalisasi!$C$54=0;0;(Normalisasi!$C$2-Normalisasi!$C$53)/Normalisasi!$C$54) | K2: =JIKA(Normalisasi!$D$54=0;0;(Normalisasi!$D$2-Normalisasi!$D$53)/Normalisasi!$D$54) | L2: =JIKA(Normalisasi!$E$54=0;0;(Normalisasi!$E$2-Normalisasi!$E$53)/Normalisasi!$E$54) | M2: =JIKA(Normalisasi!$F$54=0;0;(Normalisasi!$F$2-Normalisasi!$F$53)/Normalisasi!$F$54) | N2: =JIKA(Normalisasi!$G$54=0;0;(Normalisasi!$G$2-Normalisasi!$G$53)/Normalisasi!$G$54) | O2: =JIKA(Normalisasi!$H$54=0;0;(Normalisasi!$H$2-Normalisasi!$H$53)/Normalisasi!$H$54) | P2: =JIKA(Normalisasi!$I$54=0;0;(Normalisasi!$I$2-Normalisasi!$I$53)/Normalisasi!$I$54) | Q2: =MAKS(ABS(Normalisasi!$J$2-Normalisasi!$R$2);ABS(Normalisasi!$K$2-Normalisasi!$S$2);ABS(Normalisasi!$L$2-Normalisasi!$T$2);ABS(Normalisasi!$M$2-Normalisasi!$U$2);ABS(Normalisasi!$N$2-Normalisasi!$V$2);ABS(Normalisasi!$O$2-Normalisasi!$W$2);ABS(Normalisasi!$P$2-Normalisasi!$X$2)) | R2: 0.87823932 | S2: -0.52190721 | T2: 1.5680169 | U2: -1.2077586 | V2: 0.16477009 | W2: -0.80096418 | X2: 1.451936
A3: =Data_Awal!A3 | B3: =Data_Awal!B3 | C3: =Data_Awal!C3 | D3: =Data_Awal!D3 | E3: =Data_Awal!E3 | F3: =Data_Awal!F3 | G3: =Data_Awal!G3 | H3: =Data_Awal!H3 | I3: =Data_Awal!I3 | J3: =JIKA(Normalisasi!$C$54=0;0;(Normalisasi!$C$3-Normalisasi!$C$53)/Normalisasi!$C$54) | K3: =JIKA(Normalisasi!$D$54=0;0;(Normalisasi!$D$3-Normalisasi!$D$53)/Normalisasi!$D$54) | L3: =JIKA(Normalisasi!$E$54=0;0;(Normalisasi!$E$3-Normalisasi!$E$53)/Normalisasi!$E$54) | M3: =JIKA(Normalisasi!$F$54=0;0;(Normalisasi!$F$3-Normalisasi!$F$53)/Normalisasi!$F$54) | N3: =JIKA(Normalisasi!$G$54=0;0;(Normalisasi!$G$3-Normalisasi!$G$53)/Normalisasi!$G$54) | O3: =JIKA(Normalisasi!$H$54=0;0;(Normalisasi!$H$3-Normalisasi!$H$53)/Normalisasi!$H$54) | P3: =JIKA(Normalisasi!$I$54=0;0;(Normalisasi!$I$3-Normalisasi!$I$53)/Normalisasi!$I$54) | Q3: =MAKS(ABS(Normalisasi!$J$3-Normalisasi!$R$3);ABS(Normalisasi!$K$3-Normalisasi!$S$3);ABS(Normalisasi!$L$3-Normalisasi!$T$3);ABS(Normalisasi!$M$3-Normalisasi!$U$3);ABS(Normalisasi!$N$3-Normalisasi!$V$3);ABS(Normalisasi!$O$3-Normalisasi!$W$3);ABS(Normalisasi!$P$3-Normalisasi!$X$3)) | R3: -1.1526981 | S3: -0.94875161 | T3: -1.5152325 | U3: 1.1452589 | V3: 0.65722025 | W3: 0.66064929 | X3: -0.54385232
A4: =Data_Awal!A4 | B4: =Data_Awal!B4 | C4: =Data_Awal!C4 | D4: =Data_Awal!D4 | E4: =Data_Awal!E4 | F4: =Data_Awal!F4 | G4: =Data_Awal!G4 | H4: =Data_Awal!H4 | I4: =Data_Awal!I4 | J4: =JIKA(Normalisasi!$C$54=0;0;(Normalisasi!$C$4-Normalisasi!$C$53)/Normalisasi!$C$54) | K4: =JIKA(Normalisasi!$D$54=0;0;(Normalisasi!$D$4-Normalisasi!$D$53)/Normalisasi!$D$54) | L4: =JIKA(Normalisasi!$E$54=0;0;(Normalisasi!$E$4-Normalisasi!$E$53)/Normalisasi!$E$54) | M4: =JIKA(Normalisasi!$F$54=0;0;(Normalisasi!$F$4-Normalisasi!$F$53)/Normalisasi!$F$54) | N4: =JIKA(Normalisasi!$G$54=0;0;(Normalisasi!$G$4-Normalisasi!$G$53)/Normalisasi!$G$54) | O4: =JIKA(Normalisasi!$H$54=0;0;(Normalisasi!$H$4-Normalisasi!$H$53)/Normalisasi!$H$54) | P4: =JIKA(Normalisasi!$I$54=0;0;(Normalisasi!$I$4-Normalisasi!$I$53)/Normalisasi!$I$54) | Q4: =MAKS(ABS(Normalisasi!$J$4-Normalisasi!$R$4);ABS(Normalisasi!$K$4-Normalisasi!$S$4);ABS(Normalisasi!$L$4-Normalisasi!$T$4);ABS(Normalisasi!$M$4-Normalisasi!$U$4);ABS(Normalisasi!$N$4-Normalisasi!$V$4);ABS(Normalisasi!$O$4-Normalisasi!$W$4);ABS(Normalisasi!$P$4-Normalisasi!$X$4)) | R4: -0.25987057 | S4: 1.0630983 | T4: 1.0754695 | U4: 1.3432074 | V4: -0.78202844 | W4: -0.21631879 | X4: -0.54385232
A5: =Data_Awal!A5 | B5: =Data_Awal!B5 | C5: =Data_Awal!C5 | D5: =Data_Awal!D5 | E5: =Data_Awal!E5 | F5: =Data_Awal!F5 | G5: =Data_Awal!G5 | H5: =Data_Awal!H5 | I5: =Data_Awal!I5 | J5: =JIKA(Normalisasi!$C$54=0;0;(Normalisasi!$C$5-Normalisasi!$C$53)/Normalisasi!$C$54) | K5: =JIKA(Normalisasi!$D$54=0;0;(Normalisasi!$D$5-Normalisasi!$D$53)/Normalisasi!$D$54) | L5: =JIKA(Normalisasi!$E$54=0;0;(Normalisasi!$E$5-Normalisasi!$E$53)/Normalisasi!$E$54) | M5: =JIKA(Normalisasi!$F$54=0;0;(Normalisasi!$F$5-Normalisasi!$F$53)/Normalisasi!$F$54) | N5: =JIKA(Normalisasi!$G$54=0;0;(Normalisasi!$G$5-Normalisasi!$G$53)/Normalisasi!$G$54) | O5: =JIKA(Normalisasi!$H$54=0;0;(Normalisasi!$H$5-Normalisasi!$H$53)/Normalisasi!$H$54) | P5: =JIKA(Normalisasi!$I$54=0;0;(Normalisasi!$I$5-Normalisasi!$I$53)/Normalisasi!$I$54) | Q5: =MAKS(ABS(Normalisasi!$J$5-Normalisasi!$R$5);ABS(Normalisasi!$K$5-Normalisasi!$S$5);ABS(Normalisasi!$L$5-Normalisasi!$T$5);ABS(Normalisasi!$M$5-Normalisasi!$U$5);ABS(Normalisasi!$N$5-Normalisasi!$V$5);ABS(Normalisasi!$O$5-Normalisasi!$W$5);ABS(Normalisasi!$P$5-Normalisasi!$X$5)) | R5: 0.5830495 | S5: -1.6823681 | T5: -1.7027917 | U5: -1.048599 | V5: -1.1401721 | W5: -0.36248014 | X5: -0.29437878
A6: =Data_Awal!A6 | B6: =Data_Awal!B6 | C6: =Data_Awal!C6 | D6: =Data_Awal!D6 | E6: =Data_Awal!E6 | F6: =Data_Awal!F6 | G6: =Data_Awal!G6 | H6: =Data_Awal!H6 | I6: =Data_Awal!I6 | J6: =JIKA(Normalisasi!$C$54=0;0;(Normalisasi!$C$6-Normalisasi!$C$53)/Normalisasi!$C$54) | K6: =JIKA(Normalisasi!$D$54=0;0;(Normalisasi!$D$6-Normalisasi!$D$53)/Normalisasi!$D$54) | L6: =JIKA(Normalisasi!$E$54=0;0;(Normalisasi!$E$6-Normalisasi!$E$53)/Normalisasi!$E$54) | M6: =JIKA(Normalisasi!$F$54=0;0;(Normalisasi!$F$6-Normalisasi!$F$53)/Normalisasi!$F$54) | N6: =JIKA(Normalisasi!$G$54=0;0;(Normalisasi!$G$6-Normalisasi!$G$53)/Normalisasi!$G$54) | O6: =JIKA(Normalisasi!$H$54=0;0;(Normalisasi!$H$6-Normalisasi!$H$53)/Normalisasi!$H$54) | P6: =JIKA(Normalisasi!$I$54=0;0;(Normalisasi!$I$6-Normalisasi!$I$53)/Normalisasi!$I$54) | Q6: =MAKS(ABS(Normalisasi!$J$6-Normalisasi!$R$6);ABS(Normalisasi!$K$6-Normalisasi!$S$6);ABS(Normalisasi!$L$6-Normalisasi!$T$6);ABS(Normalisasi!$M$6-Normalisasi!$U$6);ABS(Normalisasi!$N$6-Normalisasi!$V$6);ABS(Normalisasi!$O$6-Normalisasi!$W$6);ABS(Normalisasi!$P$6-Normalisasi!$X$6)) | R6: -1.3764221 | S6: 1.055311 | T6: 0.60149484 | U6: 0.4426717 | V6: -1.2739107 | W6: -1.2394482 | X6: -0.79332587
A7: =Data_Awal!A7 | B7: =Data_Awal!B7 | C7: =Data_Awal!C7 | D7: =Data_Awal!D7 | E7: =Data_Awal!E7 | F7: =Data_Awal!F7 | G7: =Data_Awal!G7 | H7: =Data_Awal!H7 | I7: =Data_Awal!I7 | J7: =JIKA(Normalisasi!$C$54=0;0;(Normalisasi!$C$7-Normalisasi!$C$53)/Normalisasi!$C$54) | K7: =JIKA(Normalisasi!$D$54=0;0;(Normalisasi!$D$7-Normalisasi!$D$53)/Normalisasi!$D$54) | L7: =JIKA(Normalisasi!$E$54=0;0;(Normalisasi!$E$7-Normalisasi!$E$53)/Normalisasi!$E$54) | M7: =JIKA(Normalisasi!$F$54=0;0;(Normalisasi!$F$7-Normalisasi!$F$53)/Normalisasi!$F$54) | N7: =JIKA(Normalisasi!$G$54=0;0;(Normalisasi!$G$7-Normalisasi!$G$53)/Normalisasi!$G$54) | O7: =JIKA(Normalisasi!$H$54=0;0;(Normalisasi!$H$7-Normalisasi!$H$53)/Normalisasi!$H$54) | P7: =JIKA(Normalisasi!$I$54=0;0;(Normalisasi!$I$7-Normalisasi!$I$53)/Normalisasi!$I$54) | Q7: =MAKS(ABS(Normalisasi!$J$7-Normalisasi!$R$7);ABS(Normalisasi!$K$7-Normalisasi!$S$7);ABS(Normalisasi!$L$7-Normalisasi!$T$7);ABS(Normalisasi!$M$7-Normalisasi!$U$7);ABS(Normalisasi!$N$7-Normalisasi!$V$7);ABS(Normalisasi!$O$7-Normalisasi!$W$7);ABS(Normalisasi!$P$7-Normalisasi!$X$7)) | R7: -0.71336619 | S7: 0.68340357 | T7: -0.03775073 | U7: -1.4223323 | V7: 0.98183363 | W7: 0.66064929 | X7: 1.2024625
A8: =Data_Awal!A8 | B8: =Data_Awal!B8 | C8: =Data_Awal!C8 | D8: =Data_Awal!D8 | E8: =Data_Awal!E8 | F8: =Data_Awal!F8 | G8: =Data_Awal!G8 | H8: =Data_Awal!H8 | I8: =Data_Awal!I8 | J8: =JIKA(Normalisasi!$C$54=0;0;(Normalisasi!$C$8-Normalisasi!$C$53)/Normalisasi!$C$54) | K8: =JIKA(Normalisasi!$D$54=0;0;(Normalisasi!$D$8-Normalisasi!$D$53)/Normalisasi!$D$54) | L8: =JIKA(Normalisasi!$E$54=0;0;(Normalisasi!$E$8-Normalisasi!$E$53)/Normalisasi!$E$54) | M8: =JIKA(Normalisasi!$F$54=0;0;(Normalisasi!$F$8-Normalisasi!$F$53)/Normalisasi!$F$54) | N8: =JIKA(Normalisasi!$G$54=0;0;(Normalisasi!$G$8-Normalisasi!$G$53)/Normalisasi!$G$54) | O8: =JIKA(Normalisasi!$H$54=0;0;(Normalisasi!$H$8-Normalisasi!$H$53)/Normalisasi!$H$54) | P8: =JIKA(Normalisasi!$I$54=0;0;(Normalisasi!$I$8-Normalisasi!$I$53)/Normalisasi!$I$54) | Q8: =MAKS(ABS(Normalisasi!$J$8-Normalisasi!$R$8);ABS(Normalisasi!$K$8-Normalisasi!$S$8);ABS(Normalisasi!$L$8-Normalisasi!$T$8);ABS(Normalisasi!$M$8-Normalisasi!$U$8);ABS(Normalisasi!$N$8-Normalisasi!$V$8);ABS(Normalisasi!$O$8-Normalisasi!$W$8);ABS(Normalisasi!$P$8-Normalisasi!$X$8)) | R8: 0.61398913 | S8: 1.2283656 | T8: -1.4935467 | U8: -0.93807093 | V8: 0.52264473 | W8: -0.94712552 | X8: -1.5417465
A9: =Data_Awal!A9 | B9: =Data_Awal!B9 | C9: =Data_Awal!C9 | D9: =Data_Awal!D9 | E9: =Data_Awal!E9 | F9: =Data_Awal!F9 | G9: =Data_Awal!G9 | H9: =Data_Awal!H9 | I9: =Data_Awal!I9 | J9: =JIKA(Normalisasi!$C$54=0;0;(Normalisasi!$C$9-Normalisasi!$C$53)/Normalisasi!$C$54) | K9: =JIKA(Normalisasi!$D$54=0;0;(Normalisasi!$D$9-Normalisasi!$D$53)/Normalisasi!$D$54) | L9: =JIKA(Normalisasi!$E$54=0;0;(Normalisasi!$E$9-Normalisasi!$E$53)/Normalisasi!$E$54) | M9: =JIKA(Normalisasi!$F$54=0;0;(Normalisasi!$F$9-Normalisasi!$F$53)/Normalisasi!$F$54) | N9: =JIKA(Normalisasi!$G$54=0;0;(Normalisasi!$G$9-Normalisasi!$G$53)/Normalisasi!$G$54) | O9: =JIKA(Normalisasi!$H$54=0;0;(Normalisasi!$H$9-Normalisasi!$H$53)/Normalisasi!$H$54) | P9: =JIKA(Normalisasi!$I$54=0;0;(Normalisasi!$I$9-Normalisasi!$I$53)/Normalisasi!$I$54) | Q9: =MAKS(ABS(Normalisasi!$J$9-Normalisasi!$R$9);ABS(Normalisasi!$K$9-Normalisasi!$S$9);ABS(Normalisasi!$L$9-Normalisasi!$T$9);ABS(Normalisasi!$M$9-Normalisasi!$U$9);ABS(Normalisasi!$N$9-Normalisasi!$V$9);ABS(Normalisasi!$O$9-Normalisasi!$W$9);ABS(Normalisasi!$P$9-Normalisasi!$X$9)) | R9: 0.90791867 | S9: -1.2541923 | T9: 0.52512445 | U9: 1.0780204 | V9: 1.3754934 | W9: -1.5317709 | X9: -0.79332587
A10: =Data_Awal!A10 | B10: =Data_Awal!B10 | C10: =Data_Awal!C10 | D10: =Data_Awal!D10 | E10: =Data_Awal!E10 | F10: =Data_Awal!F10 | G10: =Data_Awal!G10 | H10: =Data_Awal!H10 | I10: =Data_Awal!I10 | J10: =JIKA(Normalisasi!$C$54=0;0;(Normalisasi!$C$10-Normalisasi!$C$53)/Normalisasi!$C$54) | K10: =JIKA(Normalisasi!$D$54=0;0;(Normalisasi!$D$10-Normalisasi!$D$53)/Normalisasi!$D$54) | L10: =JIKA(Normalisasi!$E$54=0;0;(Normalisasi!$E$10-Normalisasi!$E$53)/Normalisasi!$E$54) | M10: =JIKA(Normalisasi!$F$54=0;0;(Normalisasi!$F$10-Normalisasi!$F$53)/Normalisasi!$F$54) | N10: =JIKA(Normalisasi!$G$54=0;0;(Normalisasi!$G$10-Normalisasi!$G$53)/Normalisasi!$G$54) | O10: =JIKA(Normalisasi!$H$54=0;0;(Normalisasi!$H$10-Normalisasi!$H$53)/Normalisasi!$H$54) | P10: =JIKA(Normalisasi!$I$54=0;0;(Normalisasi!$I$10-Normalisasi!$I$53)/Normalisasi!$I$54) | Q10: =MAKS(ABS(Normalisasi!$J$10-Normalisasi!$R$10);ABS(Normalisasi!$K$10-Normalisasi!$S$10);ABS(Normalisasi!$L$10-Normalisasi!$T$10);ABS(Normalisasi!$M$10-Normalisasi!$U$10);ABS(Normalisasi!$N$10-Normalisasi!$V$10);ABS(Normalisasi!$O$10-Normalisasi!$W$10);ABS(Normalisasi!$P$10-Normalisasi!$X$10)) | R10: 0.32183006 | S10: 1.3671186 | T10: -1.4510699 | U10: -0.12108388 | V10: -0.5625572 | W10: -0.80096418 | X10: 0.2045683
A11: =Data_Awal!A11 | B11: =Data_Awal!B11 | C11: =Data_Awal!C11 | D11: =Data_Awal!D11 | E11: =Data_Awal!E11 | F11: =Data_Awal!F11 | G11: =Data_Awal!G11 | H11: =Data_Awal!H11 | I11: =Data_Awal!I11 | J11: =JIKA(Normalisasi!$C$54=0;0;(Normalisasi!$C$11-Normalisasi!$C$53)/Normalisasi!$C$54) | K11: =JIKA(Normalisasi!$D$54=0;0;(Normalisasi!$D$11-Normalisasi!$D$53)/Normalisasi!$D$54) | L11: =JIKA(Normalisasi!$E$54=0;0;(Normalisasi!$E$11-Normalisasi!$E$53)/Normalisasi!$E$54) | M11: =JIKA(Normalisasi!$F$54=0;0;(Normalisasi!$F$11-Normalisasi!$F$53)/Normalisasi!$F$54) | N11: =JIKA(Normalisasi!$G$54=0;0;(Normalisasi!$G$11-Normalisasi!$G$53)/Normalisasi!$G$54) | O11: =JIKA(Normalisasi!$H$54=0;0;(Normalisasi!$H$11-Normalisasi!$H$53)/Normalisasi!$H$54) | P11: =JIKA(Normalisasi!$I$54=0;0;(Normalisasi!$I$11-Normalisasi!$I$53)/Normalisasi!$I$54) | Q11: =MAKS(ABS(Normalisasi!$J$11-Normalisasi!$R$11);ABS(Normalisasi!$K$11-Normalisasi!$S$11);ABS(Normalisasi!$L$11-Normalisasi!$T$11);ABS(Normalisasi!$M$11-Normalisasi!$U$11);ABS(Normalisasi!$N$11-Normalisasi!$V$11);ABS(Normalisasi!$O$11-Normalisasi!$W$11);ABS(Normalisasi!$P$11-Normalisasi!$X$11)) | R11: 0.012806288 | S11: -0.66417496 | T11: 0.49398904 | U11: 0.83795606 | V11: 0.54638536 | W11: 0.95297198 | X11: -1.0427994
A12: =Data_Awal!A12 | B12: =Data_Awal!B12 | C12: =Data_Awal!C12 | D12: =Data_Awal!D12 | E12: =Data_Awal!E12 | F12: =Data_Awal!F12 | G12: =Data_Awal!G12 | H12: =Data_Awal!H12 | I12: =Data_Awal!I12 | J12: =JIKA(Normalisasi!$C$54=0;0;(Normalisasi!$C$12-Normalisasi!$C$53)/Normalisasi!$C$54) | K12: =JIKA(Normalisasi!$D$54=0;0;(Normalisasi!$D$12-Normalisasi!$D$53)/Normalisasi!$D$54) | L12: =JIKA(Normalisasi!$E$54=0;0;(Normalisasi!$E$12-Normalisasi!$E$53)/Normalisasi!$E$54) | M12: =JIKA(Normalisasi!$F$54=0;0;(Normalisasi!$F$12-Normalisasi!$F$53)/Normalisasi!$F$54) | N12: =JIKA(Normalisasi!$G$54=0;0;(Normalisasi!$G$12-Normalisasi!$G$53)/Normalisasi!$G$54) | O12: =JIKA(Normalisasi!$H$54=0;0;(Normalisasi!$H$12-Normalisasi!$H$53)/Normalisasi!$H$54) | P12: =JIKA(Normalisasi!$I$54=0;0;(Normalisasi!$I$12-Normalisasi!$I$53)/Normalisasi!$I$54) | Q12: =MAKS(ABS(Normalisasi!$J$12-Normalisasi!$R$12);ABS(Normalisasi!$K$12-Normalisasi!$S$12);ABS(Normalisasi!$L$12-Normalisasi!$T$12);ABS(Normalisasi!$M$12-Normalisasi!$U$12);ABS(Normalisasi!$N$12-Normalisasi!$V$12);ABS(Normalisasi!$O$12-Normalisasi!$W$12);ABS(Normalisasi!$P$12-Normalisasi!$X$12)) | R12: 1.3131001 | S12: 1.512162 | T12: 0.40990753 | U12: -0.69577659 | V12: 1.5576675 | W12: -0.94712552 | X12: -0.044905238
A13: =Data_Awal!A13 | B13: =Data_Awal!B13 | C13: =Data_Awal!C13 | D13: =Data_Awal!D13 | E13: =Data_Awal!E13 | F13: =Data_Awal!F13 | G13: =Data_Awal!G13 | H13: =Data_Awal!H13 | I13: =Data_Awal!I13 | J13: =JIKA(Normalisasi!$C$54=0;0;(Normalisasi!$C$13-Normalisasi!$C$53)/Normalisasi!$C$54) | K13: =JIKA(Normalisasi!$D$54=0;0;(Normalisasi!$D$13-Normalisasi!$D$53)/Normalisasi!$D$54) | L13: =JIKA(Normalisasi!$E$54=0;0;(Normalisasi!$E$13-Normalisasi!$E$53)/Normalisasi!$E$54) | M13: =JIKA(Normalisasi!$F$54=0;0;(Normalisasi!$F$13-Normalisasi!$F$53)/Normalisasi!$F$54) | N13: =JIKA(Normalisasi!$G$54=0;0;(Normalisasi!$G$13-Normalisasi!$G$53)/Normalisasi!$G$54) | O13: =JIKA(Normalisasi!$H$54=0;0;(Normalisasi!$H$13-Normalisasi!$H$53)/Normalisasi!$H$54) | P13: =JIKA(Normalisasi!$I$54=0;0;(Normalisasi!$I$13-Normalisasi!$I$53)/Normalisasi!$I$54) | Q13: =MAKS(ABS(Normalisasi!$J$13-Normalisasi!$R$13);ABS(Normalisasi!$K$13-Normalisasi!$S$13);ABS(Normalisasi!$L$13-Normalisasi!$T$13);ABS(Normalisasi!$M$13-Normalisasi!$U$13);ABS(Normalisasi!$N$13-Normalisasi!$V$13);ABS(Normalisasi!$O$13-Normalisasi!$W$13);ABS(Normalisasi!$P$13-Normalisasi!$X$13)) | R13: -1.0422633 | S13: -0.43491477 | T13: -1.6117626 | U13: -0.51512509 | V13: 1.558508 | W13: -0.36248014 | X13: -1.5417465
A14: =Data_Awal!A14 | B14: =Data_Awal!B14 | C14: =Data_Awal!C14 | D14: =Data_Awal!D14 | E14: =Data_Awal!E14 | F14: =Data_Awal!F14 | G14: =Data_Awal!G14 | H14: =Data_Awal!H14 | I14: =Data_Awal!I14 | J14: =JIKA(Normalisasi!$C$54=0;0;(Normalisasi!$C$14-Normalisasi!$C$53)/Normalisasi!$C$54) | K14: =JIKA(Normalisasi!$D$54=0;0;(Normalisasi!$D$14-Normalisasi!$D$53)/Normalisasi!$D$54) | L14: =JIKA(Normalisasi!$E$54=0;0;(Normalisasi!$E$14-Normalisasi!$E$53)/Normalisasi!$E$54) | M14: =JIKA(Normalisasi!$F$54=0;0;(Normalisasi!$F$14-Normalisasi!$F$53)/Normalisasi!$F$54) | N14: =JIKA(Normalisasi!$G$54=0;0;(Normalisasi!$G$14-Normalisasi!$G$53)/Normalisasi!$G$54) | O14: =JIKA(Normalisasi!$H$54=0;0;(Normalisasi!$H$14-Normalisasi!$H$53)/Normalisasi!$H$54) | P14: =JIKA(Normalisasi!$I$54=0;0;(Normalisasi!$I$14-Normalisasi!$I$53)/Normalisasi!$I$54) | Q14: =MAKS(ABS(Normalisasi!$J$14-Normalisasi!$R$14);ABS(Normalisasi!$K$14-Normalisasi!$S$14);ABS(Normalisasi!$L$14-Normalisasi!$T$14);ABS(Normalisasi!$M$14-Normalisasi!$U$14);ABS(Normalisasi!$N$14-Normalisasi!$V$14);ABS(Normalisasi!$O$14-Normalisasi!$W$14);ABS(Normalisasi!$P$14-Normalisasi!$X$14)) | R14: 1.2766455 | S14: -1.3808481 | T14: 1.031573 | U14: 1.1101154 | V14: -0.48064992 | W14: 1.391456 | X14: 0.95298893
A15: =Data_Awal!A15 | B15: =Data_Awal!B15 | C15: =Data_Awal!C15 | D15: =Data_Awal!D15 | E15: =Data_Awal!E15 | F15: =Data_Awal!F15 | G15: =Data_Awal!G15 | H15: =Data_Awal!H15 | I15: =Data_Awal!I15 | J15: =JIKA(Normalisasi!$C$54=0;0;(Normalisasi!$C$15-Normalisasi!$C$53)/Normalisasi!$C$54) | K15: =JIKA(Normalisasi!$D$54=0;0;(Normalisasi!$D$15-Normalisasi!$D$53)/Normalisasi!$D$54) | L15: =JIKA(Normalisasi!$E$54=0;0;(Normalisasi!$E$15-Normalisasi!$E$53)/Normalisasi!$E$54) | M15: =JIKA(Normalisasi!$F$54=0;0;(Normalisasi!$F$15-Normalisasi!$F$53)/Normalisasi!$F$54) | N15: =JIKA(Normalisasi!$G$54=0;0;(Normalisasi!$G$15-Normalisasi!$G$53)/Normalisasi!$G$54) | O15: =JIKA(Normalisasi!$H$54=0;0;(Normalisasi!$H$15-Normalisasi!$H$53)/Normalisasi!$H$54) | P15: =JIKA(Normalisasi!$I$54=0;0;(Normalisasi!$I$15-Normalisasi!$I$53)/Normalisasi!$I$54) | Q15: =MAKS(ABS(Normalisasi!$J$15-Normalisasi!$R$15);ABS(Normalisasi!$K$15-Normalisasi!$S$15);ABS(Normalisasi!$L$15-Normalisasi!$T$15);ABS(Normalisasi!$M$15-Normalisasi!$U$15);ABS(Normalisasi!$N$15-Normalisasi!$V$15);ABS(Normalisasi!$O$15-Normalisasi!$W$15);ABS(Normalisasi!$P$15-Normalisasi!$X$15)) | R15: -0.97032654 | S15: 1.2271942 | T15: -0.79695541 | U15: -0.93099511 | V15: -0.63162051 | W15: -1.5317709 | X15: 0.2045683
A16: =Data_Awal!A16 | B16: =Data_Awal!B16 | C16: =Data_Awal!C16 | D16: =Data_Awal!D16 | E16: =Data_Awal!E16 | F16: =Data_Awal!F16 | G16: =Data_Awal!G16 | H16: =Data_Awal!H16 | I16: =Data_Awal!I16 | J16: =JIKA(Normalisasi!$C$54=0;0;(Normalisasi!$C$16-Normalisasi!$C$53)/Normalisasi!$C$54) | K16: =JIKA(Normalisasi!$D$54=0;0;(Normalisasi!$D$16-Normalisasi!$D$53)/Normalisasi!$D$54) | L16: =JIKA(Normalisasi!$E$54=0;0;(Normalisasi!$E$16-Normalisasi!$E$53)/Normalisasi!$E$54) | M16: =JIKA(Normalisasi!$F$54=0;0;(Normalisasi!$F$16-Normalisasi!$F$53)/Normalisasi!$F$54) | N16: =JIKA(Normalisasi!$G$54=0;0;(Normalisasi!$G$16-Normalisasi!$G$53)/Normalisasi!$G$54) | O16: =JIKA(Normalisasi!$H$54=0;0;(Normalisasi!$H$16-Normalisasi!$H$53)/Normalisasi!$H$54) | P16: =JIKA(Normalisasi!$I$54=0;0;(Normalisasi!$I$16-Normalisasi!$I$53)/Normalisasi!$I$54) | Q16: =MAKS(ABS(Normalisasi!$J$16-Normalisasi!$R$16);ABS(Normalisasi!$K$16-Normalisasi!$S$16);ABS(Normalisasi!$L$16-Normalisasi!$T$16);ABS(Normalisasi!$M$16-Normalisasi!$U$16);ABS(Normalisasi!$N$16-Normalisasi!$V$16);ABS(Normalisasi!$O$16-Normalisasi!$W$16);ABS(Normalisasi!$P$16-Normalisasi!$X$16)) | R16: -1.3695086 | S16: -1.6340588 | T16: 0.27444153 | U16: 1.8540053 | V16: 0.92852467 | W16: 1.0991333 | X16: -0.044905238
A17: =Data_Awal!A17 | B17: =Data_Awal!B17 | C17: =Data_Awal!C17 | D17: =Data_Awal!D17 | E17: =Data_Awal!E17 | F17: =Data_Awal!F17 | G17: =Data_Awal!G17 | H17: =Data_Awal!H17 | I17: =Data_Awal!I17 | J17: =JIKA(Normalisasi!$C$54=0;0;(Normalisasi!$C$17-Normalisasi!$C$53)/Normalisasi!$C$54) | K17: =JIKA(Normalisasi!$D$54=0;0;(Normalisasi!$D$17-Normalisasi!$D$53)/Normalisasi!$D$54) | L17: =JIKA(Normalisasi!$E$54=0;0;(Normalisasi!$E$17-Normalisasi!$E$53)/Normalisasi!$E$54) | M17: =JIKA(Normalisasi!$F$54=0;0;(Normalisasi!$F$17-Normalisasi!$F$53)/Normalisasi!$F$54) | N17: =JIKA(Normalisasi!$G$54=0;0;(Normalisasi!$G$17-Normalisasi!$G$53)/Normalisasi!$G$54) | O17: =JIKA(Normalisasi!$H$54=0;0;(Normalisasi!$H$17-Normalisasi!$H$53)/Normalisasi!$H$54) | P17: =JIKA(Normalisasi!$I$54=0;0;(Normalisasi!$I$17-Normalisasi!$I$53)/Normalisasi!$I$54) | Q17: =MAKS(ABS(Normalisasi!$J$17-Normalisasi!$R$17);ABS(Normalisasi!$K$17-Normalisasi!$S$17);ABS(Normalisasi!$L$17-Normalisasi!$T$17);ABS(Normalisasi!$M$17-Normalisasi!$U$17);ABS(Normalisasi!$N$17-Normalisasi!$V$17);ABS(Normalisasi!$O$17-Normalisasi!$W$17);ABS(Normalisasi!$P$17-Normalisasi!$X$17)) | R17: -0.4750219 | S17: 1.4323591 | T17: 1.3925174 | U17: 0.62432653 | V17: 1.4917898 | W17: -0.21631879 | X17: -1.292273
A18: =Data_Awal!A18 | B18: =Data_Awal!B18 | C18: =Data_Awal!C18 | D18: =Data_Awal!D18 | E18: =Data_Awal!E18 | F18: =Data_Awal!F18 | G18: =Data_Awal!G18 | H18: =Data_Awal!H18 | I18: =Data_Awal!I18 | J18: =JIKA(Normalisasi!$C$54=0;0;(Normalisasi!$C$18-Normalisasi!$C$53)/Normalisasi!$C$54) | K18: =JIKA(Normalisasi!$D$54=0;0;(Normalisasi!$D$18-Normalisasi!$D$53)/Normalisasi!$D$54) | L18: =JIKA(Normalisasi!$E$54=0;0;(Normalisasi!$E$18-Normalisasi!$E$53)/Normalisasi!$E$54) | M18: =JIKA(Normalisasi!$F$54=0;0;(Normalisasi!$F$18-Normalisasi!$F$53)/Normalisasi!$F$54) | N18: =JIKA(Normalisasi!$G$54=0;0;(Normalisasi!$G$18-Normalisasi!$G$53)/Normalisasi!$G$54) | O18: =JIKA(Normalisasi!$H$54=0;0;(Normalisasi!$H$18-Normalisasi!$H$53)/Normalisasi!$H$54) | P18: =JIKA(Normalisasi!$I$54=0;0;(Normalisasi!$I$18-Normalisasi!$I$53)/Normalisasi!$I$54) | Q18: =MAKS(ABS(Normalisasi!$J$18-Normalisasi!$R$18);ABS(Normalisasi!$K$18-Normalisasi!$S$18);ABS(Normalisasi!$L$18-Normalisasi!$T$18);ABS(Normalisasi!$M$18-Normalisasi!$U$18);ABS(Normalisasi!$N$18-Normalisasi!$V$18);ABS(Normalisasi!$O$18-Normalisasi!$W$18);ABS(Normalisasi!$P$18-Normalisasi!$X$18)) | R18: 1.519877 | S18: -0.7675334 | T18: -1.0542327 | U18: -1.1344125 | V18: -0.32646503 | W18: -0.94712552 | X18: -1.0427994
A19: =Data_Awal!A19 | B19: =Data_Awal!B19 | C19: =Data_Awal!C19 | D19: =Data_Awal!D19 | E19: =Data_Awal!E19 | F19: =Data_Awal!F19 | G19: =Data_Awal!G19 | H19: =Data_Awal!H19 | I19: =Data_Awal!I19 | J19: =JIKA(Normalisasi!$C$54=0;0;(Normalisasi!$C$19-Normalisasi!$C$53)/Normalisasi!$C$54) | K19: =JIKA(Normalisasi!$D$54=0;0;(Normalisasi!$D$19-Normalisasi!$D$53)/Normalisasi!$D$54) | L19: =JIKA(Normalisasi!$E$54=0;0;(Normalisasi!$E$19-Normalisasi!$E$53)/Normalisasi!$E$54) | M19: =JIKA(Normalisasi!$F$54=0;0;(Normalisasi!$F$19-Normalisasi!$F$53)/Normalisasi!$F$54) | N19: =JIKA(Normalisasi!$G$54=0;0;(Normalisasi!$G$19-Normalisasi!$G$53)/Normalisasi!$G$54) | O19: =JIKA(Normalisasi!$H$54=0;0;(Normalisasi!$H$19-Normalisasi!$H$53)/Normalisasi!$H$54) | P19: =JIKA(Normalisasi!$I$54=0;0;(Normalisasi!$I$19-Normalisasi!$I$53)/Normalisasi!$I$54) | Q19: =MAKS(ABS(Normalisasi!$J$19-Normalisasi!$R$19);ABS(Normalisasi!$K$19-Normalisasi!$S$19);ABS(Normalisasi!$L$19-Normalisasi!$T$19);ABS(Normalisasi!$M$19-Normalisasi!$U$19);ABS(Normalisasi!$N$19-Normalisasi!$V$19);ABS(Normalisasi!$O$19-Normalisasi!$W$19);ABS(Normalisasi!$P$19-Normalisasi!$X$19)) | R19: -1.4669436 | S19: 0.11447256 | T19: -0.33455852 | U19: -0.17717302 | V19: -0.66870503 | W19: -0.94712552 | X19: -0.54385232
A20: =Data_Awal!A20 | B20: =Data_Awal!B20 | C20: =Data_Awal!C20 | D20: =Data_Awal!D20 | E20: =Data_Awal!E20 | F20: =Data_Awal!F20 | G20: =Data_Awal!G20 | H20: =Data_Awal!H20 | I20: =Data_Awal!I20 | J20: =JIKA(Normalisasi!$C$54=0;0;(Normalisasi!$C$20-Normalisasi!$C$53)/Normalisasi!$C$54) | K20: =JIKA(Normalisasi!$D$54=0;0;(Normalisasi!$D$20-Normalisasi!$D$53)/Normalisasi!$D$54) | L20: =JIKA(Normalisasi!$E$54=0;0;(Normalisasi!$E$20-Normalisasi!$E$53)/Normalisasi!$E$54) | M20: =JIKA(Normalisasi!$F$54=0;0;(Normalisasi!$F$20-Normalisasi!$F$53)/Normalisasi!$F$54) | N20: =JIKA(Normalisasi!$G$54=0;0;(Normalisasi!$G$20-Normalisasi!$G$53)/Normalisasi!$G$54) | O20: =JIKA(Normalisasi!$H$54=0;0;(Normalisasi!$H$20-Normalisasi!$H$53)/Normalisasi!$H$54) | P20: =JIKA(Normalisasi!$I$54=0;0;(Normalisasi!$I$20-Normalisasi!$I$53)/Normalisasi!$I$54) | Q20: =MAKS(ABS(Normalisasi!$J$20-Normalisasi!$R$20);ABS(Normalisasi!$K$20-Normalisasi!$S$20);ABS(Normalisasi!$L$20-Normalisasi!$T$20);ABS(Normalisasi!$M$20-Normalisasi!$U$20);ABS(Normalisasi!$N$20-Normalisasi!$V$20);ABS(Normalisasi!$O$20-Normalisasi!$W$20);ABS(Normalisasi!$P$20-Normalisasi!$X$20)) | R20: -0.34398586 | S20: -0.30634163 | T20: -1.6060496 | U20: 1.1694684 | V20: -0.68843919 | W20: -0.65480283 | X20: -0.79332587
A21: =Data_Awal!A21 | B21: =Data_Awal!B21 | C21: =Data_Awal!C21 | D21: =Data_Awal!D21 | E21: =Data_Awal!E21 | F21: =Data_Awal!F21 | G21: =Data_Awal!G21 | H21: =Data_Awal!H21 | I21: =Data_Awal!I21 | J21: =JIKA(Normalisasi!$C$54=0;0;(Normalisasi!$C$21-Normalisasi!$C$53)/Normalisasi!$C$54) | K21: =JIKA(Normalisasi!$D$54=0;0;(Normalisasi!$D$21-Normalisasi!$D$53)/Normalisasi!$D$54) | L21: =JIKA(Normalisasi!$E$54=0;0;(Normalisasi!$E$21-Normalisasi!$E$53)/Normalisasi!$E$54) | M21: =JIKA(Normalisasi!$F$54=0;0;(Normalisasi!$F$21-Normalisasi!$F$53)/Normalisasi!$F$54) | N21: =JIKA(Normalisasi!$G$54=0;0;(Normalisasi!$G$21-Normalisasi!$G$53)/Normalisasi!$G$54) | O21: =JIKA(Normalisasi!$H$54=0;0;(Normalisasi!$H$21-Normalisasi!$H$53)/Normalisasi!$H$54) | P21: =JIKA(Normalisasi!$I$54=0;0;(Normalisasi!$I$21-Normalisasi!$I$53)/Normalisasi!$I$54) | Q21: =MAKS(ABS(Normalisasi!$J$21-Normalisasi!$R$21);ABS(Normalisasi!$K$21-Normalisasi!$S$21);ABS(Normalisasi!$L$21-Normalisasi!$T$21);ABS(Normalisasi!$M$21-Normalisasi!$U$21);ABS(Normalisasi!$N$21-Normalisasi!$V$21);ABS(Normalisasi!$O$21-Normalisasi!$W$21);ABS(Normalisasi!$P$21-Normalisasi!$X$21)) | R21: 1.4859253 | S21: 0.92415985 | T21: -1.6082369 | U21: 0.12158007 | V21: 0.35322558 | W21: 1.391456 | X21: 1.7014096
A22: =Data_Awal!A22 | B22: =Data_Awal!B22 | C22: =Data_Awal!C22 | D22: =Data_Awal!D22 | E22: =Data_Awal!E22 | F22: =Data_Awal!F22 | G22: =Data_Awal!G22 | H22: =Data_Awal!H22 | I22: =Data_Awal!I22 | J22: =JIKA(Normalisasi!$C$54=0;0;(Normalisasi!$C$22-Normalisasi!$C$53)/Normalisasi!$C$54) | K22: =JIKA(Normalisasi!$D$54=0;0;(Normalisasi!$D$22-Normalisasi!$D$53)/Normalisasi!$D$54) | L22: =JIKA(Normalisasi!$E$54=0;0;(Normalisasi!$E$22-Normalisasi!$E$53)/Normalisasi!$E$54) | M22: =JIKA(Normalisasi!$F$54=0;0;(Normalisasi!$F$22-Normalisasi!$F$53)/Normalisasi!$F$54) | N22: =JIKA(Normalisasi!$G$54=0;0;(Normalisasi!$G$22-Normalisasi!$G$53)/Normalisasi!$G$54) | O22: =JIKA(Normalisasi!$H$54=0;0;(Normalisasi!$H$22-Normalisasi!$H$53)/Normalisasi!$H$54) | P22: =JIKA(Normalisasi!$I$54=0;0;(Normalisasi!$I$22-Normalisasi!$I$53)/Normalisasi!$I$54) | Q22: =MAKS(ABS(Normalisasi!$J$22-Normalisasi!$R$22);ABS(Normalisasi!$K$22-Normalisasi!$S$22);ABS(Normalisasi!$L$22-Normalisasi!$T$22);ABS(Normalisasi!$M$22-Normalisasi!$U$22);ABS(Normalisasi!$N$22-Normalisasi!$V$22);ABS(Normalisasi!$O$22-Normalisasi!$W$22);ABS(Normalisasi!$P$22-Normalisasi!$X$22)) | R22: -1.1207645 | S22: -0.439806 | T22: 1.020294 | U22: -0.75980288 | V22: 0.70952548 | W22: 0.80681063 | X22: 1.7014096
A23: =Data_Awal!A23 | B23: =Data_Awal!B23 | C23: =Data_Awal!C23 | D23: =Data_Awal!D23 | E23: =Data_Awal!E23 | F23: =Data_Awal!F23 | G23: =Data_Awal!G23 | H23: =Data_Awal!H23 | I23: =Data_Awal!I23 | J23: =JIKA(Normalisasi!$C$54=0;0;(Normalisasi!$C$23-Normalisasi!$C$53)/Normalisasi!$C$54) | K23: =JIKA(Normalisasi!$D$54=0;0;(Normalisasi!$D$23-Normalisasi!$D$53)/Normalisasi!$D$54) | L23: =JIKA(Normalisasi!$E$54=0;0;(Normalisasi!$E$23-Normalisasi!$E$53)/Normalisasi!$E$54) | M23: =JIKA(Normalisasi!$F$54=0;0;(Normalisasi!$F$23-Normalisasi!$F$53)/Normalisasi!$F$54) | N23: =JIKA(Normalisasi!$G$54=0;0;(Normalisasi!$G$23-Normalisasi!$G$53)/Normalisasi!$G$54) | O23: =JIKA(Normalisasi!$H$54=0;0;(Normalisasi!$H$23-Normalisasi!$H$53)/Normalisasi!$H$54) | P23: =JIKA(Normalisasi!$I$54=0;0;(Normalisasi!$I$23-Normalisasi!$I$53)/Normalisasi!$I$54) | Q23: =MAKS(ABS(Normalisasi!$J$23-Normalisasi!$R$23);ABS(Normalisasi!$K$23-Normalisasi!$S$23);ABS(Normalisasi!$L$23-Normalisasi!$T$23);ABS(Normalisasi!$M$23-Normalisasi!$U$23);ABS(Normalisasi!$N$23-Normalisasi!$V$23);ABS(Normalisasi!$O$23-Normalisasi!$W$23);ABS(Normalisasi!$P$23-Normalisasi!$X$23)) | R23: 0.31301687 | S23: 1.2365616 | T23: 1.4811527 | U23: 1.7110114 | V23: 1.6989579 | W23: 1.391456 | X23: -1.5417465
A24: =Data_Awal!A24 | B24: =Data_Awal!B24 | C24: =Data_Awal!C24 | D24: =Data_Awal!D24 | E24: =Data_Awal!E24 | F24: =Data_Awal!F24 | G24: =Data_Awal!G24 | H24: =Data_Awal!H24 | I24: =Data_Awal!I24 | J24: =JIKA(Normalisasi!$C$54=0;0;(Normalisasi!$C$24-Normalisasi!$C$53)/Normalisasi!$C$54) | K24: =JIKA(Normalisasi!$D$54=0;0;(Normalisasi!$D$24-Normalisasi!$D$53)/Normalisasi!$D$54) | L24: =JIKA(Normalisasi!$E$54=0;0;(Normalisasi!$E$24-Normalisasi!$E$53)/Normalisasi!$E$54) | M24: =JIKA(Normalisasi!$F$54=0;0;(Normalisasi!$F$24-Normalisasi!$F$53)/Normalisasi!$F$54) | N24: =JIKA(Normalisasi!$G$54=0;0;(Normalisasi!$G$24-Normalisasi!$G$53)/Normalisasi!$G$54) | O24: =JIKA(Normalisasi!$H$54=0;0;(Normalisasi!$H$24-Normalisasi!$H$53)/Normalisasi!$H$54) | P24: =JIKA(Normalisasi!$I$54=0;0;(Normalisasi!$I$24-Normalisasi!$I$53)/Normalisasi!$I$54) | Q24: =MAKS(ABS(Normalisasi!$J$24-Normalisasi!$R$24);ABS(Normalisasi!$K$24-Normalisasi!$S$24);ABS(Normalisasi!$L$24-Normalisasi!$T$24);ABS(Normalisasi!$M$24-Normalisasi!$U$24);ABS(Normalisasi!$N$24-Normalisasi!$V$24);ABS(Normalisasi!$O$24-Normalisasi!$W$24);ABS(Normalisasi!$P$24-Normalisasi!$X$24)) | R24: 0.64292493 | S24: 0.40785352 | T24: -0.75367317 | U24: -0.70737603 | V24: -0.85461057 | W24: 1.5376174 | X24: 0.70351539
A25: =Data_Awal!A25 | B25: =Data_Awal!B25 | C25: =Data_Awal!C25 | D25: =Data_Awal!D25 | E25: =Data_Awal!E25 | F25: =Data_Awal!F25 | G25: =Data_Awal!G25 | H25: =Data_Awal!H25 | I25: =Data_Awal!I25 | J25: =JIKA(Normalisasi!$C$54=0;0;(Normalisasi!$C$25-Normalisasi!$C$53)/Normalisasi!$C$54) | K25: =JIKA(Normalisasi!$D$54=0;0;(Normalisasi!$D$25-Normalisasi!$D$53)/Normalisasi!$D$54) | L25: =JIKA(Normalisasi!$E$54=0;0;(Normalisasi!$E$25-Normalisasi!$E$53)/Normalisasi!$E$54) | M25: =JIKA(Normalisasi!$F$54=0;0;(Normalisasi!$F$25-Normalisasi!$F$53)/Normalisasi!$F$54) | N25: =JIKA(Normalisasi!$G$54=0;0;(Normalisasi!$G$25-Normalisasi!$G$53)/Normalisasi!$G$54) | O25: =JIKA(Normalisasi!$H$54=0;0;(Normalisasi!$H$25-Normalisasi!$H$53)/Normalisasi!$H$54) | P25: =JIKA(Normalisasi!$I$54=0;0;(Normalisasi!$I$25-Normalisasi!$I$53)/Normalisasi!$I$54) | Q25: =MAKS(ABS(Normalisasi!$J$25-Normalisasi!$R$25);ABS(Normalisasi!$K$25-Normalisasi!$S$25);ABS(Normalisasi!$L$25-Normalisasi!$T$25);ABS(Normalisasi!$M$25-Normalisasi!$U$25);ABS(Normalisasi!$N$25-Normalisasi!$V$25);ABS(Normalisasi!$O$25-Normalisasi!$W$25);ABS(Normalisasi!$P$25-Normalisasi!$X$25)) | R25: 0.99250924 | S25: 0.12716071 | T25: 1.057186 | U25: 0.75253067 | V25: 0.67779815 | W25: 1.5376174 | X25: -1.292273
A26: =Data_Awal!A26 | B26: =Data_Awal!B26 | C26: =Data_Awal!C26 | D26: =Data_Awal!D26 | E26: =Data_Awal!E26 | F26: =Data_Awal!F26 | G26: =Data_Awal!G26 | H26: =Data_Awal!H26 | I26: =Data_Awal!I26 | J26: =JIKA(Normalisasi!$C$54=0;0;(Normalisasi!$C$26-Normalisasi!$C$53)/Normalisasi!$C$54) | K26: =JIKA(Normalisasi!$D$54=0;0;(Normalisasi!$D$26-Normalisasi!$D$53)/Normalisasi!$D$54) | L26: =JIKA(Normalisasi!$E$54=0;0;(Normalisasi!$E$26-Normalisasi!$E$53)/Normalisasi!$E$54) | M26: =JIKA(Normalisasi!$F$54=0;0;(Normalisasi!$F$26-Normalisasi!$F$53)/Normalisasi!$F$54) | N26: =JIKA(Normalisasi!$G$54=0;0;(Normalisasi!$G$26-Normalisasi!$G$53)/Normalisasi!$G$54) | O26: =JIKA(Normalisasi!$H$54=0;0;(Normalisasi!$H$26-Normalisasi!$H$53)/Normalisasi!$H$54) | P26: =JIKA(Normalisasi!$I$54=0;0;(Normalisasi!$I$26-Normalisasi!$I$53)/Normalisasi!$I$54) | Q26: =MAKS(ABS(Normalisasi!$J$26-Normalisasi!$R$26);ABS(Normalisasi!$K$26-Normalisasi!$S$26);ABS(Normalisasi!$L$26-Normalisasi!$T$26);ABS(Normalisasi!$M$26-Normalisasi!$U$26);ABS(Normalisasi!$N$26-Normalisasi!$V$26);ABS(Normalisasi!$O$26-Normalisasi!$W$26);ABS(Normalisasi!$P$26-Normalisasi!$X$26)) | R26: 0.78643146 | S26: 1.4806033 | T26: -0.37203626 | U26: -0.039356542 | V26: 0.92050919 | W26: 0.36832659 | X26: 1.7014096
A27: =Data_Awal!A27 | B27: =Data_Awal!B27 | C27: =Data_Awal!C27 | D27: =Data_Awal!D27 | E27: =Data_Awal!E27 | F27: =Data_Awal!F27 | G27: =Data_Awal!G27 | H27: =Data_Awal!H27 | I27: =Data_Awal!I27 | J27: =JIKA(Normalisasi!$C$54=0;0;(Normalisasi!$C$27-Normalisasi!$C$53)/Normalisasi!$C$54) | K27: =JIKA(Normalisasi!$D$54=0;0;(Normalisasi!$D$27-Normalisasi!$D$53)/Normalisasi!$D$54) | L27: =JIKA(Normalisasi!$E$54=0;0;(Normalisasi!$E$27-Normalisasi!$E$53)/Normalisasi!$E$54) | M27: =JIKA(Normalisasi!$F$54=0;0;(Normalisasi!$F$27-Normalisasi!$F$53)/Normalisasi!$F$54) | N27: =JIKA(Normalisasi!$G$54=0;0;(Normalisasi!$G$27-Normalisasi!$G$53)/Normalisasi!$G$54) | O27: =JIKA(Normalisasi!$H$54=0;0;(Normalisasi!$H$27-Normalisasi!$H$53)/Normalisasi!$H$54) | P27: =JIKA(Normalisasi!$I$54=0;0;(Normalisasi!$I$27-Normalisasi!$I$53)/Normalisasi!$I$54) | Q27: =MAKS(ABS(Normalisasi!$J$27-Normalisasi!$R$27);ABS(Normalisasi!$K$27-Normalisasi!$S$27);ABS(Normalisasi!$L$27-Normalisasi!$T$27);ABS(Normalisasi!$M$27-Normalisasi!$U$27);ABS(Normalisasi!$N$27-Normalisasi!$V$27);ABS(Normalisasi!$O$27-Normalisasi!$W$27);ABS(Normalisasi!$P$27-Normalisasi!$X$27)) | R27: -0.88514027 | S27: 0.27482489 | T27: 0.18013376 | U27: 0.35468752 | V27: -0.67780326 | W27: -0.21631879 | X27: 0.70351539
A28: =Data_Awal!A28 | B28: =Data_Awal!B28 | C28: =Data_Awal!C28 | D28: =Data_Awal!D28 | E28: =Data_Awal!E28 | F28: =Data_Awal!F28 | G28: =Data_Awal!G28 | H28: =Data_Awal!H28 | I28: =Data_Awal!I28 | J28: =JIKA(Normalisasi!$C$54=0;0;(Normalisasi!$C$28-Normalisasi!$C$53)/Normalisasi!$C$54) | K28: =JIKA(Normalisasi!$D$54=0;0;(Normalisasi!$D$28-Normalisasi!$D$53)/Normalisasi!$D$54) | L28: =JIKA(Normalisasi!$E$54=0;0;(Normalisasi!$E$28-Normalisasi!$E$53)/Normalisasi!$E$54) | M28: =JIKA(Normalisasi!$F$54=0;0;(Normalisasi!$F$28-Normalisasi!$F$53)/Normalisasi!$F$54) | N28: =JIKA(Normalisasi!$G$54=0;0;(Normalisasi!$G$28-Normalisasi!$G$53)/Normalisasi!$G$54) | O28: =JIKA(Normalisasi!$H$54=0;0;(Normalisasi!$H$28-Normalisasi!$H$53)/Normalisasi!$H$54) | P28: =JIKA(Normalisasi!$I$54=0;0;(Normalisasi!$I$28-Normalisasi!$I$53)/Normalisasi!$I$54) | Q28: =MAKS(ABS(Normalisasi!$J$28-Normalisasi!$R$28);ABS(Normalisasi!$K$28-Normalisasi!$S$28);ABS(Normalisasi!$L$28-Normalisasi!$T$28);ABS(Normalisasi!$M$28-Normalisasi!$U$28);ABS(Normalisasi!$N$28-Normalisasi!$V$28);ABS(Normalisasi!$O$28-Normalisasi!$W$28);ABS(Normalisasi!$P$28-Normalisasi!$X$28)) | R28: -0.92296871 | S28: -0.82796227 | T28: 1.1704676 | U28: -1.0095642 | V28: 1.4273554 | W28: 1.5376174 | X28: 1.451936
A29: =Data_Awal!A29 | B29: =Data_Awal!B29 | C29: =Data_Awal!C29 | D29: =Data_Awal!D29 | E29: =Data_Awal!E29 | F29: =Data_Awal!F29 | G29: =Data_Awal!G29 | H29: =Data_Awal!H29 | I29: =Data_Awal!I29 | J29: =JIKA(Normalisasi!$C$54=0;0;(Normalisasi!$C$29-Normalisasi!$C$53)/Normalisasi!$C$54) | K29: =JIKA(Normalisasi!$D$54=0;0;(Normalisasi!$D$29-Normalisasi!$D$53)/Normalisasi!$D$54) | L29: =JIKA(Normalisasi!$E$54=0;0;(Normalisasi!$E$29-Normalisasi!$E$53)/Normalisasi!$E$54) | M29: =JIKA(Normalisasi!$F$54=0;0;(Normalisasi!$F$29-Normalisasi!$F$53)/Normalisasi!$F$54) | N29: =JIKA(Normalisasi!$G$54=0;0;(Normalisasi!$G$29-Normalisasi!$G$53)/Normalisasi!$G$54) | O29: =JIKA(Normalisasi!$H$54=0;0;(Normalisasi!$H$29-Normalisasi!$H$53)/Normalisasi!$H$54) | P29: =JIKA(Normalisasi!$I$54=0;0;(Normalisasi!$I$29-Normalisasi!$I$53)/Normalisasi!$I$54) | Q29: =MAKS(ABS(Normalisasi!$J$29-Normalisasi!$R$29);ABS(Normalisasi!$K$29-Normalisasi!$S$29);ABS(Normalisasi!$L$29-Normalisasi!$T$29);ABS(Normalisasi!$M$29-Normalisasi!$U$29);ABS(Normalisasi!$N$29-Normalisasi!$V$29);ABS(Normalisasi!$O$29-Normalisasi!$W$29);ABS(Normalisasi!$P$29-Normalisasi!$X$29)) | R29: 0.4400279 | S29: 0.42482343 | T29: 1.5688015 | U29: -0.96309833 | V29: -0.42487182 | W29: 0.95297198 | X29: 0.2045683
A30: =Data_Awal!A30 | B30: =Data_Awal!B30 | C30: =Data_Awal!C30 | D30: =Data_Awal!D30 | E30: =Data_Awal!E30 | F30: =Data_Awal!F30 | G30: =Data_Awal!G30 | H30: =Data_Awal!H30 | I30: =Data_Awal!I30 | J30: =JIKA(Normalisasi!$C$54=0;0;(Normalisasi!$C$30-Normalisasi!$C$53)/Normalisasi!$C$54) | K30: =JIKA(Normalisasi!$D$54=0;0;(Normalisasi!$D$30-Normalisasi!$D$53)/Normalisasi!$D$54) | L30: =JIKA(Normalisasi!$E$54=0;0;(Normalisasi!$E$30-Normalisasi!$E$53)/Normalisasi!$E$54) | M30: =JIKA(Normalisasi!$F$54=0;0;(Normalisasi!$F$30-Normalisasi!$F$53)/Normalisasi!$F$54) | N30: =JIKA(Normalisasi!$G$54=0;0;(Normalisasi!$G$30-Normalisasi!$G$53)/Normalisasi!$G$54) | O30: =JIKA(Normalisasi!$H$54=0;0;(Normalisasi!$H$30-Normalisasi!$H$53)/Normalisasi!$H$54) | P30: =JIKA(Normalisasi!$I$54=0;0;(Normalisasi!$I$30-Normalisasi!$I$53)/Normalisasi!$I$54) | Q30: =MAKS(ABS(Normalisasi!$J$30-Normalisasi!$R$30);ABS(Normalisasi!$K$30-Normalisasi!$S$30);ABS(Normalisasi!$L$30-Normalisasi!$T$30);ABS(Normalisasi!$M$30-Normalisasi!$U$30);ABS(Normalisasi!$N$30-Normalisasi!$V$30);ABS(Normalisasi!$O$30-Normalisasi!$W$30);ABS(Normalisasi!$P$30-Normalisasi!$X$30)) | R30: -1.2533649 | S30: -1.8055726 | T30: 1.007848 | U30: 0.043669211 | V30: -0.75715549 | W30: -1.5317709 | X30: 0.45404185
A31: =Data_Awal!A31 | B31: =Data_Awal!B31 | C31: =Data_Awal!C31 | D31: =Data_Awal!D31 | E31: =Data_Awal!E31 | F31: =Data_Awal!F31 | G31: =Data_Awal!G31 | H31: =Data_Awal!H31 | I31: =Data_Awal!I31 | J31: =JIKA(Normalisasi!$C$54=0;0;(Normalisasi!$C$31-Normalisasi!$C$53)/Normalisasi!$C$54) | K31: =JIKA(Normalisasi!$D$54=0;0;(Normalisasi!$D$31-Normalisasi!$D$53)/Normalisasi!$D$54) | L31: =JIKA(Normalisasi!$E$54=0;0;(Normalisasi!$E$31-Normalisasi!$E$53)/Normalisasi!$E$54) | M31: =JIKA(Normalisasi!$F$54=0;0;(Normalisasi!$F$31-Normalisasi!$F$53)/Normalisasi!$F$54) | N31: =JIKA(Normalisasi!$G$54=0;0;(Normalisasi!$G$31-Normalisasi!$G$53)/Normalisasi!$G$54) | O31: =JIKA(Normalisasi!$H$54=0;0;(Normalisasi!$H$31-Normalisasi!$H$53)/Normalisasi!$H$54) | P31: =JIKA(Normalisasi!$I$54=0;0;(Normalisasi!$I$31-Normalisasi!$I$53)/Normalisasi!$I$54) | Q31: =MAKS(ABS(Normalisasi!$J$31-Normalisasi!$R$31);ABS(Normalisasi!$K$31-Normalisasi!$S$31);ABS(Normalisasi!$L$31-Normalisasi!$T$31);ABS(Normalisasi!$M$31-Normalisasi!$U$31);ABS(Normalisasi!$N$31-Normalisasi!$V$31);ABS(Normalisasi!$O$31-Normalisasi!$W$31);ABS(Normalisasi!$P$31-Normalisasi!$X$31)) | R31: -1.1683544 | S31: 1.4922479 | T31: -1.4216968 | U31: -1.5071083 | V31: -0.58360411 | W31: -0.94712552 | X31: 1.2024625
A32: =Data_Awal!A32 | B32: =Data_Awal!B32 | C32: =Data_Awal!C32 | D32: =Data_Awal!D32 | E32: =Data_Awal!E32 | F32: =Data_Awal!F32 | G32: =Data_Awal!G32 | H32: =Data_Awal!H32 | I32: =Data_Awal!I32 | J32: =JIKA(Normalisasi!$C$54=0;0;(Normalisasi!$C$32-Normalisasi!$C$53)/Normalisasi!$C$54) | K32: =JIKA(Normalisasi!$D$54=0;0;(Normalisasi!$D$32-Normalisasi!$D$53)/Normalisasi!$D$54) | L32: =JIKA(Normalisasi!$E$54=0;0;(Normalisasi!$E$32-Normalisasi!$E$53)/Normalisasi!$E$54) | M32: =JIKA(Normalisasi!$F$54=0;0;(Normalisasi!$F$32-Normalisasi!$F$53)/Normalisasi!$F$54) | N32: =JIKA(Normalisasi!$G$54=0;0;(Normalisasi!$G$32-Normalisasi!$G$53)/Normalisasi!$G$54) | O32: =JIKA(Normalisasi!$H$54=0;0;(Normalisasi!$H$32-Normalisasi!$H$53)/Normalisasi!$H$54) | P32: =JIKA(Normalisasi!$I$54=0;0;(Normalisasi!$I$32-Normalisasi!$I$53)/Normalisasi!$I$54) | Q32: =MAKS(ABS(Normalisasi!$J$32-Normalisasi!$R$32);ABS(Normalisasi!$K$32-Normalisasi!$S$32);ABS(Normalisasi!$L$32-Normalisasi!$T$32);ABS(Normalisasi!$M$32-Normalisasi!$U$32);ABS(Normalisasi!$N$32-Normalisasi!$V$32);ABS(Normalisasi!$O$32-Normalisasi!$W$32);ABS(Normalisasi!$P$32-Normalisasi!$X$32)) | R32: -0.65815534 | S32: 1.0093842 | T32: -1.0498449 | U32: -1.1316169 | V32: -1.3019362 | W32: 0.36832659 | X32: 1.2024625
A33: =Data_Awal!A33 | B33: =Data_Awal!B33 | C33: =Data_Awal!C33 | D33: =Data_Awal!D33 | E33: =Data_Awal!E33 | F33: =Data_Awal!F33 | G33: =Data_Awal!G33 | H33: =Data_Awal!H33 | I33: =Data_Awal!I33 | J33: =JIKA(Normalisasi!$C$54=0;0;(Normalisasi!$C$33-Normalisasi!$C$53)/Normalisasi!$C$54) | K33: =JIKA(Normalisasi!$D$54=0;0;(Normalisasi!$D$33-Normalisasi!$D$53)/Normalisasi!$D$54) | L33: =JIKA(Normalisasi!$E$54=0;0;(Normalisasi!$E$33-Normalisasi!$E$53)/Normalisasi!$E$54) | M33: =JIKA(Normalisasi!$F$54=0;0;(Normalisasi!$F$33-Normalisasi!$F$53)/Normalisasi!$F$54) | N33: =JIKA(Normalisasi!$G$54=0;0;(Normalisasi!$G$33-Normalisasi!$G$53)/Normalisasi!$G$54) | O33: =JIKA(Normalisasi!$H$54=0;0;(Normalisasi!$H$33-Normalisasi!$H$53)/Normalisasi!$H$54) | P33: =JIKA(Normalisasi!$I$54=0;0;(Normalisasi!$I$33-Normalisasi!$I$53)/Normalisasi!$I$54) | Q33: =MAKS(ABS(Normalisasi!$J$33-Normalisasi!$R$33);ABS(Normalisasi!$K$33-Normalisasi!$S$33);ABS(Normalisasi!$L$33-Normalisasi!$T$33);ABS(Normalisasi!$M$33-Normalisasi!$U$33);ABS(Normalisasi!$N$33-Normalisasi!$V$33);ABS(Normalisasi!$O$33-Normalisasi!$W$33);ABS(Normalisasi!$P$33-Normalisasi!$X$33)) | R33: -0.057970555 | S33: -1.729211 | T33: -1.0832977 | U33: -0.76877902 | V33: -1.2967186 | W33: -0.65480283 | X33: -1.5417465
A34: =Data_Awal!A34 | B34: =Data_Awal!B34 | C34: =Data_Awal!C34 | D34: =Data_Awal!D34 | E34: =Data_Awal!E34 | F34: =Data_Awal!F34 | G34: =Data_Awal!G34 | H34: =Data_Awal!H34 | I34: =Data_Awal!I34 | J34: =JIKA(Normalisasi!$C$54=0;0;(Normalisasi!$C$34-Normalisasi!$C$53)/Normalisasi!$C$54) | K34: =JIKA(Normalisasi!$D$54=0;0;(Normalisasi!$D$34-Normalisasi!$D$53)/Normalisasi!$D$54) | L34: =JIKA(Normalisasi!$E$54=0;0;(Normalisasi!$E$34-Normalisasi!$E$53)/Normalisasi!$E$54) | M34: =JIKA(Normalisasi!$F$54=0;0;(Normalisasi!$F$34-Normalisasi!$F$53)/Normalisasi!$F$54) | N34: =JIKA(Normalisasi!$G$54=0;0;(Normalisasi!$G$34-Normalisasi!$G$53)/Normalisasi!$G$54) | O34: =JIKA(Normalisasi!$H$54=0;0;(Normalisasi!$H$34-Normalisasi!$H$53)/Normalisasi!$H$54) | P34: =JIKA(Normalisasi!$I$54=0;0;(Normalisasi!$I$34-Normalisasi!$I$53)/Normalisasi!$I$54) | Q34: =MAKS(ABS(Normalisasi!$J$34-Normalisasi!$R$34);ABS(Normalisasi!$K$34-Normalisasi!$S$34);ABS(Normalisasi!$L$34-Normalisasi!$T$34);ABS(Normalisasi!$M$34-Normalisasi!$U$34);ABS(Normalisasi!$N$34-Normalisasi!$V$34);ABS(Normalisasi!$O$34-Normalisasi!$W$34);ABS(Normalisasi!$P$34-Normalisasi!$X$34)) | R34: 0.49869514 | S34: 1.0942155 | T34: 0.19556761 | U34: -0.019866388 | V34: 1.3543097 | W34: 0.51448794 | X34: -0.79332587
A35: =Data_Awal!A35 | B35: =Data_Awal!B35 | C35: =Data_Awal!C35 | D35: =Data_Awal!D35 | E35: =Data_Awal!E35 | F35: =Data_Awal!F35 | G35: =Data_Awal!G35 | H35: =Data_Awal!H35 | I35: =Data_Awal!I35 | J35: =JIKA(Normalisasi!$C$54=0;0;(Normalisasi!$C$35-Normalisasi!$C$53)/Normalisasi!$C$54) | K35: =JIKA(Normalisasi!$D$54=0;0;(Normalisasi!$D$35-Normalisasi!$D$53)/Normalisasi!$D$54) | L35: =JIKA(Normalisasi!$E$54=0;0;(Normalisasi!$E$35-Normalisasi!$E$53)/Normalisasi!$E$54) | M35: =JIKA(Normalisasi!$F$54=0;0;(Normalisasi!$F$35-Normalisasi!$F$53)/Normalisasi!$F$54) | N35: =JIKA(Normalisasi!$G$54=0;0;(Normalisasi!$G$35-Normalisasi!$G$53)/Normalisasi!$G$54) | O35: =JIKA(Normalisasi!$H$54=0;0;(Normalisasi!$H$35-Normalisasi!$H$53)/Normalisasi!$H$54) | P35: =JIKA(Normalisasi!$I$54=0;0;(Normalisasi!$I$35-Normalisasi!$I$53)/Normalisasi!$I$54) | Q35: =MAKS(ABS(Normalisasi!$J$35-Normalisasi!$R$35);ABS(Normalisasi!$K$35-Normalisasi!$S$35);ABS(Normalisasi!$L$35-Normalisasi!$T$35);ABS(Normalisasi!$M$35-Normalisasi!$U$35);ABS(Normalisasi!$N$35-Normalisasi!$V$35);ABS(Normalisasi!$O$35-Normalisasi!$W$35);ABS(Normalisasi!$P$35-Normalisasi!$X$35)) | R35: -0.92755824 | S35: -1.0039047 | T35: 0.67850504 | U35: -1.119172 | V35: 0.21356934 | W35: -1.3856096 | X35: 0.45404185
A36: =Data_Awal!A36 | B36: =Data_Awal!B36 | C36: =Data_Awal!C36 | D36: =Data_Awal!D36 | E36: =Data_Awal!E36 | F36: =Data_Awal!F36 | G36: =Data_Awal!G36 | H36: =Data_Awal!H36 | I36: =Data_Awal!I36 | J36: =JIKA(Normalisasi!$C$54=0;0;(Normalisasi!$C$36-Normalisasi!$C$53)/Normalisasi!$C$54) | K36: =JIKA(Normalisasi!$D$54=0;0;(Normalisasi!$D$36-Normalisasi!$D$53)/Normalisasi!$D$54) | L36: =JIKA(Normalisasi!$E$54=0;0;(Normalisasi!$E$36-Normalisasi!$E$53)/Normalisasi!$E$54) | M36: =JIKA(Normalisasi!$F$54=0;0;(Normalisasi!$F$36-Normalisasi!$F$53)/Normalisasi!$F$54) | N36: =JIKA(Normalisasi!$G$54=0;0;(Normalisasi!$G$36-Normalisasi!$G$53)/Normalisasi!$G$54) | O36: =JIKA(Normalisasi!$H$54=0;0;(Normalisasi!$H$36-Normalisasi!$H$53)/Normalisasi!$H$54) | P36: =JIKA(Normalisasi!$I$54=0;0;(Normalisasi!$I$36-Normalisasi!$I$53)/Normalisasi!$I$54) | Q36: =MAKS(ABS(Normalisasi!$J$36-Normalisasi!$R$36);ABS(Normalisasi!$K$36-Normalisasi!$S$36);ABS(Normalisasi!$L$36-Normalisasi!$T$36);ABS(Normalisasi!$M$36-Normalisasi!$U$36);ABS(Normalisasi!$N$36-Normalisasi!$V$36);ABS(Normalisasi!$O$36-Normalisasi!$W$36);ABS(Normalisasi!$P$36-Normalisasi!$X$36)) | R36: 1.3424072 | S36: -0.40087524 | T36: -0.33211255 | U36: 0.031318403 | V36: -1.1391859 | W36: -1.5317709 | X36: -0.54385232
A37: =Data_Awal!A37 | B37: =Data_Awal!B37 | C37: =Data_Awal!C37 | D37: =Data_Awal!D37 | E37: =Data_Awal!E37 | F37: =Data_Awal!F37 | G37: =Data_Awal!G37 | H37: =Data_Awal!H37 | I37: =Data_Awal!I37 | J37: =JIKA(Normalisasi!$C$54=0;0;(Normalisasi!$C$37-Normalisasi!$C$53)/Normalisasi!$C$54) | K37: =JIKA(Normalisasi!$D$54=0;0;(Normalisasi!$D$37-Normalisasi!$D$53)/Normalisasi!$D$54) | L37: =JIKA(Normalisasi!$E$54=0;0;(Normalisasi!$E$37-Normalisasi!$E$53)/Normalisasi!$E$54) | M37: =JIKA(Normalisasi!$F$54=0;0;(Normalisasi!$F$37-Normalisasi!$F$53)/Normalisasi!$F$54) | N37: =JIKA(Normalisasi!$G$54=0;0;(Normalisasi!$G$37-Normalisasi!$G$53)/Normalisasi!$G$54) | O37: =JIKA(Normalisasi!$H$54=0;0;(Normalisasi!$H$37-Normalisasi!$H$53)/Normalisasi!$H$54) | P37: =JIKA(Normalisasi!$I$54=0;0;(Normalisasi!$I$37-Normalisasi!$I$53)/Normalisasi!$I$54) | Q37: =MAKS(ABS(Normalisasi!$J$37-Normalisasi!$R$37);ABS(Normalisasi!$K$37-Normalisasi!$S$37);ABS(Normalisasi!$L$37-Normalisasi!$T$37);ABS(Normalisasi!$M$37-Normalisasi!$U$37);ABS(Normalisasi!$N$37-Normalisasi!$V$37);ABS(Normalisasi!$O$37-Normalisasi!$W$37);ABS(Normalisasi!$P$37-Normalisasi!$X$37)) | R37: 0.93182016 | S37: 1.1113432 | T37: 0.78753455 | U37: 0.83136497 | V37: -0.60965404 | W37: -1.0932869 | X37: 0.2045683
A38: =Data_Awal!A38 | B38: =Data_Awal!B38 | C38: =Data_Awal!C38 | D38: =Data_Awal!D38 | E38: =Data_Awal!E38 | F38: =Data_Awal!F38 | G38: =Data_Awal!G38 | H38: =Data_Awal!H38 | I38: =Data_Awal!I38 | J38: =JIKA(Normalisasi!$C$54=0;0;(Normalisasi!$C$38-Normalisasi!$C$53)/Normalisasi!$C$54) | K38: =JIKA(Normalisasi!$D$54=0;0;(Normalisasi!$D$38-Normalisasi!$D$53)/Normalisasi!$D$54) | L38: =JIKA(Normalisasi!$E$54=0;0;(Normalisasi!$E$38-Normalisasi!$E$53)/Normalisasi!$E$54) | M38: =JIKA(Normalisasi!$F$54=0;0;(Normalisasi!$F$38-Normalisasi!$F$53)/Normalisasi!$F$54) | N38: =JIKA(Normalisasi!$G$54=0;0;(Normalisasi!$G$38-Normalisasi!$G$53)/Normalisasi!$G$54) | O38: =JIKA(Normalisasi!$H$54=0;0;(Normalisasi!$H$38-Normalisasi!$H$53)/Normalisasi!$H$54) | P38: =JIKA(Normalisasi!$I$54=0;0;(Normalisasi!$I$38-Normalisasi!$I$53)/Normalisasi!$I$54) | Q38: =MAKS(ABS(Normalisasi!$J$38-Normalisasi!$R$38);ABS(Normalisasi!$K$38-Normalisasi!$S$38);ABS(Normalisasi!$L$38-Normalisasi!$T$38);ABS(Normalisasi!$M$38-Normalisasi!$U$38);ABS(Normalisasi!$N$38-Normalisasi!$V$38);ABS(Normalisasi!$O$38-Normalisasi!$W$38);ABS(Normalisasi!$P$38-Normalisasi!$X$38)) | R38: -1.7920315 | S38: 0.7014139 | T38: -0.51005011 | U38: 0.4925519 | V38: 0.80547766 | W38: -0.070157446 | X38: -0.29437878
A39: =Data_Awal!A39 | B39: =Data_Awal!B39 | C39: =Data_Awal!C39 | D39: =Data_Awal!D39 | E39: =Data_Awal!E39 | F39: =Data_Awal!F39 | G39: =Data_Awal!G39 | H39: =Data_Awal!H39 | I39: =Data_Awal!I39 | J39: =JIKA(Normalisasi!$C$54=0;0;(Normalisasi!$C$39-Normalisasi!$C$53)/Normalisasi!$C$54) | K39: =JIKA(Normalisasi!$D$54=0;0;(Normalisasi!$D$39-Normalisasi!$D$53)/Normalisasi!$D$54) | L39: =JIKA(Normalisasi!$E$54=0;0;(Normalisasi!$E$39-Normalisasi!$E$53)/Normalisasi!$E$54) | M39: =JIKA(Normalisasi!$F$54=0;0;(Normalisasi!$F$39-Normalisasi!$F$53)/Normalisasi!$F$54) | N39: =JIKA(Normalisasi!$G$54=0;0;(Normalisasi!$G$39-Normalisasi!$G$53)/Normalisasi!$G$54) | O39: =JIKA(Normalisasi!$H$54=0;0;(Normalisasi!$H$39-Normalisasi!$H$53)/Normalisasi!$H$54) | P39: =JIKA(Normalisasi!$I$54=0;0;(Normalisasi!$I$39-Normalisasi!$I$53)/Normalisasi!$I$54) | Q39: =MAKS(ABS(Normalisasi!$J$39-Normalisasi!$R$39);ABS(Normalisasi!$K$39-Normalisasi!$S$39);ABS(Normalisasi!$L$39-Normalisasi!$T$39);ABS(Normalisasi!$M$39-Normalisasi!$U$39);ABS(Normalisasi!$N$39-Normalisasi!$V$39);ABS(Normalisasi!$O$39-Normalisasi!$W$39);ABS(Normalisasi!$P$39-Normalisasi!$X$39)) | R39: -0.7401042 | S39: -1.1763648 | T39: 0.46697153 | U39: 1.7247562 | V39: 0.25033829 | W39: -1.5317709 | X39: 1.451936
A40: =Data_Awal!A40 | B40: =Data_Awal!B40 | C40: =Data_Awal!C40 | D40: =Data_Awal!D40 | E40: =Data_Awal!E40 | F40: =Data_Awal!F40 | G40: =Data_Awal!G40 | H40: =Data_Awal!H40 | I40: =Data_Awal!I40 | J40: =JIKA(Normalisasi!$C$54=0;0;(Normalisasi!$C$40-Normalisasi!$C$53)/Normalisasi!$C$54) | K40: =JIKA(Normalisasi!$D$54=0;0;(Normalisasi!$D$40-Normalisasi!$D$53)/Normalisasi!$D$54) | L40: =JIKA(Normalisasi!$E$54=0;0;(Normalisasi!$E$40-Normalisasi!$E$53)/Normalisasi!$E$54) | M40: =JIKA(Normalisasi!$F$54=0;0;(Normalisasi!$F$40-Normalisasi!$F$53)/Normalisasi!$F$54) | N40: =JIKA(Normalisasi!$G$54=0;0;(Normalisasi!$G$40-Normalisasi!$G$53)/Normalisasi!$G$54) | O40: =JIKA(Normalisasi!$H$54=0;0;(Normalisasi!$H$40-Normalisasi!$H$53)/Normalisasi!$H$54) | P40: =JIKA(Normalisasi!$I$54=0;0;(Normalisasi!$I$40-Normalisasi!$I$53)/Normalisasi!$I$54) | Q40: =MAKS(ABS(Normalisasi!$J$40-Normalisasi!$R$40);ABS(Normalisasi!$K$40-Normalisasi!$S$40);ABS(Normalisasi!$L$40-Normalisasi!$T$40);ABS(Normalisasi!$M$40-Normalisasi!$U$40);ABS(Normalisasi!$N$40-Normalisasi!$V$40);ABS(Normalisasi!$O$40-Normalisasi!$W$40);ABS(Normalisasi!$P$40-Normalisasi!$X$40)) | R40: -0.74685544 | S40: 0.14759607 | T40: -0.95516642 | U40: 1.2903053 | V40: 0.48576591 | W40: -1.0932869 | X40: -1.292273
...

Sheet Inisialisasi
A1: Centroid Awal (K-Means++ — indeks baris POI di Data_Awal)
A3: Cluster | B3: Baris POI | C3: POI ID | D3: Nama POI | E3: Z Latitude | F3: Z Longitude | G3: Z Semantic Score | H3: Z Jarak Hotel (m) | I3: Z Jarak Halte (m) | J3: Z Restoran 500m | K3: Z Minimarket 500m
A4: C0 | B4: 42 | C4: =Data_Awal!A42 | D4: =Data_Awal!B42 | E4: =Normalisasi!J42 | F4: =Normalisasi!K42 | G4: =Normalisasi!L42 | H4: =Normalisasi!M42 | I4: =Normalisasi!N42 | J4: =Normalisasi!O42 | K4: =Normalisasi!P42
A5: C1 | B5: 17 | C5: =Data_Awal!A17 | D5: =Data_Awal!B17 | E5: =Normalisasi!J17 | F5: =Normalisasi!K17 | G5: =Normalisasi!L17 | H5: =Normalisasi!M17 | I5: =Normalisasi!N17 | J5: =Normalisasi!O17 | K5: =Normalisasi!P17
A6: C2 | B6: 47 | C6: =Data_Awal!A47 | D6: =Data_Awal!B47 | E6: =Normalisasi!J47 | F6: =Normalisasi!K47 | G6: =Normalisasi!L47 | H6: =Normalisasi!M47 | I6: =Normalisasi!N47 | J6: =Normalisasi!O47 | K6: =Normalisasi!P47

Sheet Konvergensi
A1: Iterasi Intelligent K-Means (rumus Excel + referensi Python)
A3: ITER 0 — Centroid Awal
A4: Cluster | B4: Z Latitude | C4: Z Longitude | D4: Z Semantic Score | E4: Z Jarak Hotel (m) | F4: Z Jarak Halte (m) | G4: Z Restoran 500m | H4: Z Minimarket 500m
A5: C0 | B5: =Inisialisasi!E4 | C5: =Inisialisasi!F4 | D5: =Inisialisasi!G4 | E5: =Inisialisasi!H4 | F5: =Inisialisasi!I4 | G5: =Inisialisasi!J4 | H5: =Inisialisasi!K4
A6: C1 | B6: =Inisialisasi!E5 | C6: =Inisialisasi!F5 | D6: =Inisialisasi!G5 | E6: =Inisialisasi!H5 | F6: =Inisialisasi!I5 | G6: =Inisialisasi!J5 | H6: =Inisialisasi!K5
A7: C2 | B7: =Inisialisasi!E6 | C7: =Inisialisasi!F6 | D7: =Inisialisasi!G6 | E7: =Inisialisasi!H6 | F7: =Inisialisasi!I6 | G7: =Inisialisasi!J6 | H7: =Inisialisasi!K6
A9: ITER 1 — Assignment & Centroid Baru
A10: POI ID | B10: Nama | C10: d(C0) | D10: d(C1) | E10: d(C2) | F10: Cluster | G10: WCSS POI | H10: Py Cluster | I10: Py WCSS
A11: =Data_Awal!A2 | B11: =Data_Awal!B2 | C11: =AKAR(JUMLAH(PANGKAT(Normalisasi!$J$2-Konvergensi!$B$5;2);PANGKAT(Normalisasi!$K$2-Konvergensi!$C$5;2);PANGKAT(Normalisasi!$L$2-Konvergensi!$D$5;2);PANGKAT(Normalisasi!$M$2-Konvergensi!$E$5;2);PANGKAT(Normalisasi!$N$2-Konvergensi!$F$5;2);PANGKAT(Normalisasi!$O$2-Konvergensi!$G$5;2);PANGKAT(Normalisasi!$P$2-Konvergensi!$H$5;2))) | D11: =AKAR(JUMLAH(PANGKAT(Normalisasi!$J$2-Konvergensi!$B$6;2);PANGKAT(Normalisasi!$K$2-Konvergensi!$C$6;2);PANGKAT(Normalisasi!$L$2-Konvergensi!$D$6;2);PANGKAT(Normalisasi!$M$2-Konvergensi!$E$6;2);PANGKAT(Normalisasi!$N$2-Konvergensi!$F$6;2);PANGKAT(Normalisasi!$O$2-Konvergensi!$G$6;2);PANGKAT(Normalisasi!$P$2-Konvergensi!$H$6;2))) | E11: =AKAR(JUMLAH(PANGKAT(Normalisasi!$J$2-Konvergensi!$B$7;2);PANGKAT(Normalisasi!$K$2-Konvergensi!$C$7;2);PANGKAT(Normalisasi!$L$2-Konvergensi!$D$7;2);PANGKAT(Normalisasi!$M$2-Konvergensi!$E$7;2);PANGKAT(Normalisasi!$N$2-Konvergensi!$F$7;2);PANGKAT(Normalisasi!$O$2-Konvergensi!$G$7;2);PANGKAT(Normalisasi!$P$2-Konvergensi!$H$7;2))) | F11: =JIKA(C11<=D11;=JIKA(C11<=E11;0;2);=JIKA(D11<=E11;1;2)) | G11: =JUMLAH(JIKA(F11=0;JUMLAH(PANGKAT(Normalisasi!$J$2-Konvergensi!$B$64;2);PANGKAT(Normalisasi!$K$2-Konvergensi!$C$64;2);PANGKAT(Normalisasi!$L$2-Konvergensi!$D$64;2);PANGKAT(Normalisasi!$M$2-Konvergensi!$E$64;2);PANGKAT(Normalisasi!$N$2-Konvergensi!$F$64;2);PANGKAT(Normalisasi!$O$2-Konvergensi!$G$64;2);PANGKAT(Normalisasi!$P$2-Konvergensi!$H$64;2));0);JIKA(F11=1;JUMLAH(PANGKAT(Normalisasi!$J$2-Konvergensi!$B$65;2);PANGKAT(Normalisasi!$K$2-Konvergensi!$C$65;2);PANGKAT(Normalisasi!$L$2-Konvergensi!$D$65;2);PANGKAT(Normalisasi!$M$2-Konvergensi!$E$65;2);PANGKAT(Normalisasi!$N$2-Konvergensi!$F$65;2);PANGKAT(Normalisasi!$O$2-Konvergensi!$G$65;2);PANGKAT(Normalisasi!$P$2-Konvergensi!$H$65;2));0);JIKA(F11=2;JUMLAH(PANGKAT(Normalisasi!$J$2-Konvergensi!$B$66;2);PANGKAT(Normalisasi!$K$2-Konvergensi!$C$66;2);PANGKAT(Normalisasi!$L$2-Konvergensi!$D$66;2);PANGKAT(Normalisasi!$M$2-Konvergensi!$E$66;2);PANGKAT(Normalisasi!$N$2-Konvergensi!$F$66;2);PANGKAT(Normalisasi!$O$2-Konvergensi!$G$66;2);PANGKAT(Normalisasi!$P$2-Konvergensi!$H$66;2));0)) | H11: 0 | I11: 6.6515152
A12: =Data_Awal!A3 | B12: =Data_Awal!B3 | C12: =AKAR(JUMLAH(PANGKAT(Normalisasi!$J$3-Konvergensi!$B$5;2);PANGKAT(Normalisasi!$K$3-Konvergensi!$C$5;2);PANGKAT(Normalisasi!$L$3-Konvergensi!$D$5;2);PANGKAT(Normalisasi!$M$3-Konvergensi!$E$5;2);PANGKAT(Normalisasi!$N$3-Konvergensi!$F$5;2);PANGKAT(Normalisasi!$O$3-Konvergensi!$G$5;2);PANGKAT(Normalisasi!$P$3-Konvergensi!$H$5;2))) | D12: =AKAR(JUMLAH(PANGKAT(Normalisasi!$J$3-Konvergensi!$B$6;2);PANGKAT(Normalisasi!$K$3-Konvergensi!$C$6;2);PANGKAT(Normalisasi!$L$3-Konvergensi!$D$6;2);PANGKAT(Normalisasi!$M$3-Konvergensi!$E$6;2);PANGKAT(Normalisasi!$N$3-Konvergensi!$F$6;2);PANGKAT(Normalisasi!$O$3-Konvergensi!$G$6;2);PANGKAT(Normalisasi!$P$3-Konvergensi!$H$6;2))) | E12: =AKAR(JUMLAH(PANGKAT(Normalisasi!$J$3-Konvergensi!$B$7;2);PANGKAT(Normalisasi!$K$3-Konvergensi!$C$7;2);PANGKAT(Normalisasi!$L$3-Konvergensi!$D$7;2);PANGKAT(Normalisasi!$M$3-Konvergensi!$E$7;2);PANGKAT(Normalisasi!$N$3-Konvergensi!$F$7;2);PANGKAT(Normalisasi!$O$3-Konvergensi!$G$7;2);PANGKAT(Normalisasi!$P$3-Konvergensi!$H$7;2))) | F12: =JIKA(C12<=D12;=JIKA(C12<=E12;0;2);=JIKA(D12<=E12;1;2)) | G12: =JUMLAH(JIKA(F12=0;JUMLAH(PANGKAT(Normalisasi!$J$3-Konvergensi!$B$64;2);PANGKAT(Normalisasi!$K$3-Konvergensi!$C$64;2);PANGKAT(Normalisasi!$L$3-Konvergensi!$D$64;2);PANGKAT(Normalisasi!$M$3-Konvergensi!$E$64;2);PANGKAT(Normalisasi!$N$3-Konvergensi!$F$64;2);PANGKAT(Normalisasi!$O$3-Konvergensi!$G$64;2);PANGKAT(Normalisasi!$P$3-Konvergensi!$H$64;2));0);JIKA(F12=1;JUMLAH(PANGKAT(Normalisasi!$J$3-Konvergensi!$B$65;2);PANGKAT(Normalisasi!$K$3-Konvergensi!$C$65;2);PANGKAT(Normalisasi!$L$3-Konvergensi!$D$65;2);PANGKAT(Normalisasi!$M$3-Konvergensi!$E$65;2);PANGKAT(Normalisasi!$N$3-Konvergensi!$F$65;2);PANGKAT(Normalisasi!$O$3-Konvergensi!$G$65;2);PANGKAT(Normalisasi!$P$3-Konvergensi!$H$65;2));0);JIKA(F12=2;JUMLAH(PANGKAT(Normalisasi!$J$3-Konvergensi!$B$66;2);PANGKAT(Normalisasi!$K$3-Konvergensi!$C$66;2);PANGKAT(Normalisasi!$L$3-Konvergensi!$D$66;2);PANGKAT(Normalisasi!$M$3-Konvergensi!$E$66;2);PANGKAT(Normalisasi!$N$3-Konvergensi!$F$66;2);PANGKAT(Normalisasi!$O$3-Konvergensi!$G$66;2);PANGKAT(Normalisasi!$P$3-Konvergensi!$H$66;2));0)) | H12: 2 | I12: 8.612129
